Workbook

Sheet Read Me
A1: DELIVERY BASELINE 1.0
A2: 7 September 2026 | 262 work packages | 27 domains | All implementation statuses start at Not started
A5: Section | B5: How to use
A6: Architecture | B6: Read Customer_Action_OS_Production_Architecture_v1.docx first. This workbook is the editable task and evidence register.
A7: Feature Tracker | B7: Filter by domain, gate, squad or status. Assign people, estimate effort, set dates and link implementation/test evidence.
A8: Status | B8: Use Not started, In progress, Blocked, Review or Done. Done requires implementation, tests, review, documentation and release evidence.
A9: Verified completion | B9: Completion counts Done rows only when an evidence link exists. A link still requires independent reviewer validation.
A10: Evidence gate | B10: A Done item without an evidence link is flagged MISSING EVIDENCE. External approval is a separate gate.
A11: Scope traceability | B11: All 61 numbered sections of the approved plan map to work-package groups and architecture sections.
A12: Capacity Model | B12: Blue input cells are editable assumptions. Derived rates, storage and cell counts use formulas. This is not benchmark evidence.
A13: Release Gates | B13: G0–G3 sequence implementation; G4 separately certifies actual fleet scale. No feature completion proves provider permission.
A14: Approval Gates | B14: Open decisions and required provider, legal and engineering evidence must be resolved by named owners.
A15: Source register | B15: Official URLs, retrieval status and limitations are recorded. Some Meta developer pages were not retrievable.
A16: Safe edits | B16: Keep task IDs stable. Add child tickets in your project system rather than silently deleting baseline requirements.
... A19: Progress claim | B19: No rows were marked implemented or approved. Owner, estimate, date and evidence fields are intentionally blank.

Sheet Dashboard
A1: DELIVERY COMMAND CENTER
A2: Verified completion requires Done + an evidence link. Reviewer validation and provider approval remain separate.
A4: Total tasks | B4: Verified done | C4: Verified % | D4: In progress | E4: Blocked | F4: In review | G4: No assignee | H4: Done / no evidence
A5: =COUNTA('Feature Tracker'!A6:A267) -> 262 | B5: =SUM('Feature Tracker'!J6:J267) -> 0 | C5: =IFERROR(B5/A5,0) -> 0 | D5: =COUNTIF('Feature Tracker'!I6:I267,"In progress") -> 0 | E5: =COUNTIF('Feature Tracker'!I6:I267,"Blocked") -> 0 | F5: =COUNTIF('Feature Tracker'!I6:I267,"Review") -> 0 | G5: =COUNTBLANK('Feature Tracker'!G6:G267) -> 262 | H5: =COUNTIFS('Feature Tracker'!I6:I267,"Done",'Feature Tracker'!N6:N267,"") -> 0
A8: Domain | B8: Tasks | C8: Verified done | D8: Verified % | E8: In progress | F8: Blocked | G8: Review | H8: Not started
A9: Architecture and governance | B9: =COUNTIF('Feature Tracker'!B6:B267,A9) -> 7 | C9: =SUMIF('Feature Tracker'!B6:B267,A9,'Feature Tracker'!J6:J267) -> 0 | D9: =IFERROR(C9/B9,0) -> 0 | E9: =COUNTIFS('Feature Tracker'!B6:B267,A9,'Feature Tracker'!I6:I267,"In progress") -> 0 | F9: =COUNTIFS('Feature Tracker'!B6:B267,A9,'Feature Tracker'!I6:I267,"Blocked") -> 0 | G9: =COUNTIFS('Feature Tracker'!B6:B267,A9,'Feature Tracker'!I6:I267,"Review") -> 0 | H9: =COUNTIFS('Feature Tracker'!B6:B267,A9,'Feature Tracker'!I6:I267,"Not started") -> 7
A10: Tenant platform | B10: =COUNTIF('Feature Tracker'!B6:B267,A10) -> 12 | C10: =SUMIF('Feature Tracker'!B6:B267,A10,'Feature Tracker'!J6:J267) -> 0 | D10: =IFERROR(C10/B10,0) -> 0 | E10: =COUNTIFS('Feature Tracker'!B6:B267,A10,'Feature Tracker'!I6:I267,"In progress") -> 0 | F10: =COUNTIFS('Feature Tracker'!B6:B267,A10,'Feature Tracker'!I6:I267,"Blocked") -> 0 | G10: =COUNTIFS('Feature Tracker'!B6:B267,A10,'Feature Tracker'!I6:I267,"Review") -> 0 | H10: =COUNTIFS('Feature Tracker'!B6:B267,A10,'Feature Tracker'!I6:I267,"Not started") -> 12
A11: Data persistence | B11: =COUNTIF('Feature Tracker'!B6:B267,A11) -> 10 | C11: =SUMIF('Feature Tracker'!B6:B267,A11,'Feature Tracker'!J6:J267) -> 0 | D11: =IFERROR(C11/B11,0) -> 0 | E11: =COUNTIFS('Feature Tracker'!B6:B267,A11,'Feature Tracker'!I6:I267,"In progress") -> 0 | F11: =COUNTIFS('Feature Tracker'!B6:B267,A11,'Feature Tracker'!I6:I267,"Blocked") -> 0 | G11: =COUNTIFS('Feature Tracker'!B6:B267,A11,'Feature Tracker'!I6:I267,"Review") -> 0 | H11: =COUNTIFS('Feature Tracker'!B6:B267,A11,'Feature Tracker'!I6:I267,"Not started") -> 10
A12: Event and queue backbone | B12: =COUNTIF('Feature Tracker'!B6:B267,A12) -> 12 | C12: =SUMIF('Feature Tracker'!B6:B267,A12,'Feature Tracker'!J6:J267) -> 0 | D12: =IFERROR(C12/B12,0) -> 0 | E12: =COUNTIFS('Feature Tracker'!B6:B267,A12,'Feature Tracker'!I6:I267,"In progress") -> 0 | F12: =COUNTIFS('Feature Tracker'!B6:B267,A12,'Feature Tracker'!I6:I267,"Blocked") -> 0 | G12: =COUNTIFS('Feature Tracker'!B6:B267,A12,'Feature Tracker'!I6:I267,"Review") -> 0 | H12: =COUNTIFS('Feature Tracker'!B6:B267,A12,'Feature Tracker'!I6:I267,"Not started") -> 12
A13: WhatsApp and Meta onboarding | B13: =COUNTIF('Feature Tracker'!B6:B267,A13) -> 12 | C13: =SUMIF('Feature Tracker'!B6:B267,A13,'Feature Tracker'!J6:J267) -> 0 | D13: =IFERROR(C13/B13,0) -> 0 | E13: =COUNTIFS('Feature Tracker'!B6:B267,A13,'Feature Tracker'!I6:I267,"In progress") -> 0 | F13: =COUNTIFS('Feature Tracker'!B6:B267,A13,'Feature Tracker'!I6:I267,"Blocked") -> 0 | G13: =COUNTIFS('Feature Tracker'!B6:B267,A13,'Feature Tracker'!I6:I267,"Review") -> 0 | H13: =COUNTIFS('Feature Tracker'!B6:B267,A13,'Feature Tracker'!I6:I267,"Not started") -> 12
A14: Instagram, Messenger and Ads | B14: =COUNTIF('Feature Tracker'!B6:B267,A14) -> 8 | C14: =SUMIF('Feature Tracker'!B6:B267,A14,'Feature Tracker'!J6:J267) -> 0 | D14: =IFERROR(C14/B14,0) -> 0 | E14: =COUNTIFS('Feature Tracker'!B6:B267,A14,'Feature Tracker'!I6:I267,"In progress") -> 0 | F14: =COUNTIFS('Feature Tracker'!B6:B267,A14,'Feature Tracker'!I6:I267,"Blocked") -> 0 | G14: =COUNTIFS('Feature Tracker'!B6:B267,A14,'Feature Tracker'!I6:I267,"Review") -> 0 | H14: =COUNTIFS('Feature Tracker'!B6:B267,A14,'Feature Tracker'!I6:I267,"Not started") -> 8
A15: Telegram and channel expansion | B15: =COUNTIF('Feature Tracker'!B6:B267,A15) -> 8 | C15: =SUMIF('Feature Tracker'!B6:B267,A15,'Feature Tracker'!J6:J267) -> 0 | D15: =IFERROR(C15/B15,0) -> 0 | E15: =COUNTIFS('Feature Tracker'!B6:B267,A15,'Feature Tracker'!I6:I267,"In progress") -> 0 | F15: =COUNTIFS('Feature Tracker'!B6:B267,A15,'Feature Tracker'!I6:I267,"Blocked") -> 0 | G15: =COUNTIFS('Feature Tracker'!B6:B267,A15,'Feature Tracker'!I6:I267,"Review") -> 0 | H15: =COUNTIFS('Feature Tracker'!B6:B267,A15,'Feature Tracker'!I6:I267,"Not started") -> 8
A16: Messaging and unified inbox | B16: =COUNTIF('Feature Tracker'!B6:B267,A16) -> 12 | C16: =SUMIF('Feature Tracker'!B6:B267,A16,'Feature Tracker'!J6:J267) -> 0 | D16: =IFERROR(C16/B16,0) -> 0 | E16: =COUNTIFS('Feature Tracker'!B6:B267,A16,'Feature Tracker'!I6:I267,"In progress") -> 0 | F16: =COUNTIFS('Feature Tracker'!B6:B267,A16,'Feature Tracker'!I6:I267,"Blocked") -> 0 | G16: =COUNTIFS('Feature Tracker'!B6:B267,A16,'Feature Tracker'!I6:I267,"Review") -> 0 | H16: =COUNTIFS('Feature Tracker'!B6:B267,A16,'Feature Tracker'!I6:I267,"Not started") -> 12
A17: Customer webhooks | B17: =COUNTIF('Feature Tracker'!B6:B267,A17) -> 10 | C17: =SUMIF('Feature Tracker'!B6:B267,A17,'Feature Tracker'!J6:J267) -> 0 | D17: =IFERROR(C17/B17,0) -> 0 | E17: =COUNTIFS('Feature Tracker'!B6:B267,A17,'Feature Tracker'!I6:I267,"In progress") -> 0 | F17: =COUNTIFS('Feature Tracker'!B6:B267,A17,'Feature Tracker'!I6:I267,"Blocked") -> 0 | G17: =COUNTIFS('Feature Tracker'!B6:B267,A17,'Feature Tracker'!I6:I267,"Review") -> 0 | H17: =COUNTIFS('Feature Tracker'!B6:B267,A17,'Feature Tracker'!I6:I267,"Not started") -> 10
A18: Customer state and consent | B18: =COUNTIF('Feature Tracker'!B6:B267,A18) -> 8 | C18: =SUMIF('Feature Tracker'!B6:B267,A18,'Feature Tracker'!J6:J267) -> 0 | D18: =IFERROR(C18/B18,0) -> 0 | E18: =COUNTIFS('Feature Tracker'!B6:B267,A18,'Feature Tracker'!I6:I267,"In progress") -> 0 | F18: =COUNTIFS('Feature Tracker'!B6:B267,A18,'Feature Tracker'!I6:I267,"Blocked") -> 0 | G18: =COUNTIFS('Feature Tracker'!B6:B267,A18,'Feature Tracker'!I6:I267,"Review") -> 0 | H18: =COUNTIFS('Feature Tracker'!B6:B267,A18,'Feature Tracker'!I6:I267,"Not started") -> 8
A19: Mission and experience compiler | B19: =COUNTIF('Feature Tracker'!B6:B267,A19) -> 9 | C19: =SUMIF('Feature Tracker'!B6:B267,A19,'Feature Tracker'!J6:J267) -> 0 | D19: =IFERROR(C19/B19,0) -> 0 | E19: =COUNTIFS('Feature Tracker'!B6:B267,A19,'Feature Tracker'!I6:I267,"In progress") -> 0 | F19: =COUNTIFS('Feature Tracker'!B6:B267,A19,'Feature Tracker'!I6:I267,"Blocked") -> 0 | G19: =COUNTIFS('Feature Tracker'!B6:B267,A19,'Feature Tracker'!I6:I267,"Review") -> 0 | H19: =COUNTIFS('Feature Tracker'!B6:B267,A19,'Feature Tracker'!I6:I267,"Not started") -> 9
A20: Workflow studio and runtime | B20: =COUNTIF('Feature Tracker'!B6:B267,A20) -> 12 | C20: =SUMIF('Feature Tracker'!B6:B267,A20,'Feature Tracker'!J6:J267) -> 0 | D20: =IFERROR(C20/B20,0) -> 0 | E20: =COUNTIFS('Feature Tracker'!B6:B267,A20,'Feature Tracker'!I6:I267,"In progress") -> 0 | F20: =COUNTIFS('Feature Tracker'!B6:B267,A20,'Feature Tracker'!I6:I267,"Blocked") -> 0 | G20: =COUNTIFS('Feature Tracker'!B6:B267,A20,'Feature Tracker'!I6:I267,"Review") -> 0 | H20: =COUNTIFS('Feature Tracker'!B6:B267,A20,'Feature Tracker'!I6:I267,"Not started") -> 12
A21: Policy and verified actions | B21: =COUNTIF('Feature Tracker'!B6:B267,A21) -> 10 | C21: =SUMIF('Feature Tracker'!B6:B267,A21,'Feature Tracker'!J6:J267) -> 0 | D21: =IFERROR(C21/B21,0) -> 0 | E21: =COUNTIFS('Feature Tracker'!B6:B267,A21,'Feature Tracker'!I6:I267,"In progress") -> 0 | F21: =COUNTIFS('Feature Tracker'!B6:B267,A21,'Feature Tracker'!I6:I267,"Blocked") -> 0 | G21: =COUNTIFS('Feature Tracker'!B6:B267,A21,'Feature Tracker'!I6:I267,"Review") -> 0 | H21: =COUNTIFS('Feature Tracker'!B6:B267,A21,'Feature Tracker'!I6:I267,"Not started") -> 10
A22: Journey twin and controlled change | B22: =COUNTIF('Feature Tracker'!B6:B267,A22) -> 8 | C22: =SUMIF('Feature Tracker'!B6:B267,A22,'Feature Tracker'!J6:J267) -> 0 | D22: =IFERROR(C22/B22,0) -> 0 | E22: =COUNTIFS('Feature Tracker'!B6:B267,A22,'Feature Tracker'!I6:I267,"In progress") -> 0 | F22: =COUNTIFS('Feature Tracker'!B6:B267,A22,'Feature Tracker'!I6:I267,"Blocked") -> 0 | G22: =COUNTIFS('Feature Tracker'!B6:B267,A22,'Feature Tracker'!I6:I267,"Review") -> 0 | H22: =COUNTIFS('Feature Tracker'!B6:B267,A22,'Feature Tracker'!I6:I267,"Not started") -> 8
A23: AI agents and knowledge | B23: =COUNTIF('Feature Tracker'!B6:B267,A23) -> 12 | C23: =SUMIF('Feature Tracker'!B6:B267,A23,'Feature Tracker'!J6:J267) -> 0 | D23: =IFERROR(C23/B23,0) -> 0 | E23: =COUNTIFS('Feature Tracker'!B6:B267,A23,'Feature Tracker'!I6:I267,"In progress") -> 0 | F23: =COUNTIFS('Feature Tracker'!B6:B267,A23,'Feature Tracker'!I6:I267,"Blocked") -> 0 | G23: =COUNTIFS('Feature Tracker'!B6:B267,A23,'Feature Tracker'!I6:I267,"Review") -> 0 | H23: =COUNTIFS('Feature Tracker'!B6:B267,A23,'Feature Tracker'!I6:I267,"Not started") -> 12
A24: Integration platform | B24: =COUNTIF('Feature Tracker'!B6:B267,A24) -> 12 | C24: =SUMIF('Feature Tracker'!B6:B267,A24,'Feature Tracker'!J6:J267) -> 0 | D24: =IFERROR(C24/B24,0) -> 0 | E24: =COUNTIFS('Feature Tracker'!B6:B267,A24,'Feature Tracker'!I6:I267,"In progress") -> 0 | F24: =COUNTIFS('Feature Tracker'!B6:B267,A24,'Feature Tracker'!I6:I267,"Blocked") -> 0 | G24: =COUNTIFS('Feature Tracker'!B6:B267,A24,'Feature Tracker'!I6:I267,"Review") -> 0 | H24: =COUNTIFS('Feature Tracker'!B6:B267,A24,'Feature Tracker'!I6:I267,"Not started") -> 12
A25: Public developer platform | B25: =COUNTIF('Feature Tracker'!B6:B267,A25) -> 8 | C25: =SUMIF('Feature Tracker'!B6:B267,A25,'Feature Tracker'!J6:J267) -> 0 | D25: =IFERROR(C25/B25,0) -> 0 | E25: =COUNTIFS('Feature Tracker'!B6:B267,A25,'Feature Tracker'!I6:I267,"In progress") -> 0 | F25: =COUNTIFS('Feature Tracker'!B6:B267,A25,'Feature Tracker'!I6:I267,"Blocked") -> 0 | G25: =COUNTIFS('Feature Tracker'!B6:B267,A25,'Feature Tracker'!I6:I267,"Review") -> 0 | H25: =COUNTIFS('Feature Tracker'!B6:B267,A25,'Feature Tracker'!I6:I267,"Not started") -> 8
A26: Web, mobile and accessibility | B26: =COUNTIF('Feature Tracker'!B6:B267,A26) -> 10 | C26: =SUMIF('Feature Tracker'!B6:B267,A26,'Feature Tracker'!J6:J267) -> 0 | D26: =IFERROR(C26/B26,0) -> 0 | E26: =COUNTIFS('Feature Tracker'!B6:B267,A26,'Feature Tracker'!I6:I267,"In progress") -> 0 | F26: =COUNTIFS('Feature Tracker'!B6:B267,A26,'Feature Tracker'!I6:I267,"Blocked") -> 0 | G26: =COUNTIFS('Feature Tracker'!B6:B267,A26,'Feature Tracker'!I6:I267,"Review") -> 0 | H26: =COUNTIFS('Feature Tracker'!B6:B267,A26,'Feature Tracker'!I6:I267,"Not started") -> 10
A27: Campaigns and marketing | B27: =COUNTIF('Feature Tracker'!B6:B267,A27) -> 8 | C27: =SUMIF('Feature Tracker'!B6:B267,A27,'Feature Tracker'!J6:J267) -> 0 | D27: =IFERROR(C27/B27,0) -> 0 | E27: =COUNTIFS('Feature Tracker'!B6:B267,A27,'Feature Tracker'!I6:I267,"In progress") -> 0 | F27: =COUNTIFS('Feature Tracker'!B6:B267,A27,'Feature Tracker'!I6:I267,"Blocked") -> 0 | G27: =COUNTIFS('Feature Tracker'!B6:B267,A27,'Feature Tracker'!I6:I267,"Review") -> 0 | H27: =COUNTIFS('Feature Tracker'!B6:B267,A27,'Feature Tracker'!I6:I267,"Not started") -> 8
A28: CRM, commerce and appointments | B28: =COUNTIF('Feature Tracker'!B6:B267,A28) -> 8 | C28: =SUMIF('Feature Tracker'!B6:B267,A28,'Feature Tracker'!J6:J267) -> 0 | D28: =IFERROR(C28/B28,0) -> 0 | E28: =COUNTIFS('Feature Tracker'!B6:B267,A28,'Feature Tracker'!I6:I267,"In progress") -> 0 | F28: =COUNTIFS('Feature Tracker'!B6:B267,A28,'Feature Tracker'!I6:I267,"Blocked") -> 0 | G28: =COUNTIFS('Feature Tracker'!B6:B267,A28,'Feature Tracker'!I6:I267,"Review") -> 0 | H28: =COUNTIFS('Feature Tracker'!B6:B267,A28,'Feature Tracker'!I6:I267,"Not started") -> 8
A29: Voice and calling | B29: =COUNTIF('Feature Tracker'!B6:B267,A29) -> 6 | C29: =SUMIF('Feature Tracker'!B6:B267,A29,'Feature Tracker'!J6:J267) -> 0 | D29: =IFERROR(C29/B29,0) -> 0 | E29: =COUNTIFS('Feature Tracker'!B6:B267,A29,'Feature Tracker'!I6:I267,"In progress") -> 0 | F29: =COUNTIFS('Feature Tracker'!B6:B267,A29,'Feature Tracker'!I6:I267,"Blocked") -> 0 | G29: =COUNTIFS('Feature Tracker'!B6:B267,A29,'Feature Tracker'!I6:I267,"Review") -> 0 | H29: =COUNTIFS('Feature Tracker'!B6:B267,A29,'Feature Tracker'!I6:I267,"Not started") -> 6
A30: Support and diagnostics | B30: =COUNTIF('Feature Tracker'!B6:B267,A30) -> 8 | C30: =SUMIF('Feature Tracker'!B6:B267,A30,'Feature Tracker'!J6:J267) -> 0 | D30: =IFERROR(C30/B30,0) -> 0 | E30: =COUNTIFS('Feature Tracker'!B6:B267,A30,'Feature Tracker'!I6:I267,"In progress") -> 0 | F30: =COUNTIFS('Feature Tracker'!B6:B267,A30,'Feature Tracker'!I6:I267,"Blocked") -> 0 | G30: =COUNTIFS('Feature Tracker'!B6:B267,A30,'Feature Tracker'!I6:I267,"Review") -> 0 | H30: =COUNTIFS('Feature Tracker'!B6:B267,A30,'Feature Tracker'!I6:I267,"Not started") -> 8
A31: Billing and outcome analytics | B31: =COUNTIF('Feature Tracker'!B6:B267,A31) -> 8 | C31: =SUMIF('Feature Tracker'!B6:B267,A31,'Feature Tracker'!J6:J267) -> 0 | D31: =IFERROR(C31/B31,0) -> 0 | E31: =COUNTIFS('Feature Tracker'!B6:B267,A31,'Feature Tracker'!I6:I267,"In progress") -> 0 | F31: =COUNTIFS('Feature Tracker'!B6:B267,A31,'Feature Tracker'!I6:I267,"Blocked") -> 0 | G31: =COUNTIFS('Feature Tracker'!B6:B267,A31,'Feature Tracker'!I6:I267,"Review") -> 0 | H31: =COUNTIFS('Feature Tracker'!B6:B267,A31,'Feature Tracker'!I6:I267,"Not started") -> 8
A32: Security and privacy | B32: =COUNTIF('Feature Tracker'!B6:B267,A32) -> 12 | C32: =SUMIF('Feature Tracker'!B6:B267,A32,'Feature Tracker'!J6:J267) -> 0 | D32: =IFERROR(C32/B32,0) -> 0 | E32: =COUNTIFS('Feature Tracker'!B6:B267,A32,'Feature Tracker'!I6:I267,"In progress") -> 0 | F32: =COUNTIFS('Feature Tracker'!B6:B267,A32,'Feature Tracker'!I6:I267,"Blocked") -> 0 | G32: =COUNTIFS('Feature Tracker'!B6:B267,A32,'Feature Tracker'!I6:I267,"Review") -> 0 | H32: =COUNTIFS('Feature Tracker'!B6:B267,A32,'Feature Tracker'!I6:I267,"Not started") -> 12
A33: Platform operations and scale | B33: =COUNTIF('Feature Tracker'!B6:B267,A33) -> 12 | C33: =SUMIF('Feature Tracker'!B6:B267,A33,'Feature Tracker'!J6:J267) -> 0 | D33: =IFERROR(C33/B33,0) -> 0 | E33: =COUNTIFS('Feature Tracker'!B6:B267,A33,'Feature Tracker'!I6:I267,"In progress") -> 0 | F33: =COUNTIFS('Feature Tracker'!B6:B267,A33,'Feature Tracker'!I6:I267,"Blocked") -> 0 | G33: =COUNTIFS('Feature Tracker'!B6:B267,A33,'Feature Tracker'!I6:I267,"Review") -> 0 | H33: =COUNTIFS('Feature Tracker'!B6:B267,A33,'Feature Tracker'!I6:I267,"Not started") -> 12
A34: Verification and external approvals | B34: =COUNTIF('Feature Tracker'!B6:B267,A34) -> 12 | C34: =SUMIF('Feature Tracker'!B6:B267,A34,'Feature Tracker'!J6:J267) -> 0 | D34: =IFERROR(C34/B34,0) -> 0 | E34: =COUNTIFS('Feature Tracker'!B6:B267,A34,'Feature Tracker'!I6:I267,"In progress") -> 0 | F34: =COUNTIFS('Feature Tracker'!B6:B267,A34,'Feature Tracker'!I6:I267,"Blocked") -> 0 | G34: =COUNTIFS('Feature Tracker'!B6:B267,A34,'Feature Tracker'!I6:I267,"Review") -> 0 | H34: =COUNTIFS('Feature Tracker'!B6:B267,A34,'Feature Tracker'!I6:I267,"Not started") -> 12
A35: Agency and marketplace | B35: =COUNTIF('Feature Tracker'!B6:B267,A35) -> 8 | C35: =SUMIF('Feature Tracker'!B6:B267,A35,'Feature Tracker'!J6:J267) -> 0 | D35: =IFERROR(C35/B35,0) -> 0 | E35: =COUNTIFS('Feature Tracker'!B6:B267,A35,'Feature Tracker'!I6:I267,"In progress") -> 0 | F35: =COUNTIFS('Feature Tracker'!B6:B267,A35,'Feature Tracker'!I6:I267,"Blocked") -> 0 | G35: =COUNTIFS('Feature Tracker'!B6:B267,A35,'Feature Tracker'!I6:I267,"Review") -> 0 | H35: =COUNTIFS('Feature Tracker'!B6:B267,A35,'Feature Tracker'!I6:I267,"Not started") -> 8
A38: Implementation gate | B38: Tasks | C38: Verified done | D38: Verified %
A39: G0 | B39: =COUNTIF('Feature Tracker'!D6:D267,A39) -> 60 | C39: =SUMIF('Feature Tracker'!D6:D267,A39,'Feature Tracker'!J6:J267) -> 0 | D39: =IFERROR(C39/B39,0) -> 0
A40: G1 | B40: =COUNTIF('Feature Tracker'!D6:D267,A40) -> 126 | C40: =SUMIF('Feature Tracker'!D6:D267,A40,'Feature Tracker'!J6:J267) -> 0 | D40: =IFERROR(C40/B40,0) -> 0
A41: G2 | B41: =COUNTIF('Feature Tracker'!D6:D267,A41) -> 59 | C41: =SUMIF('Feature Tracker'!D6:D267,A41,'Feature Tracker'!J6:J267) -> 0 | D41: =IFERROR(C41/B41,0) -> 0
A42: G3 | B42: =COUNTIF('Feature Tracker'!D6:D267,A42) -> 17 | C42: =SUMIF('Feature Tracker'!D6:D267,A42,'Feature Tracker'!J6:J267) -> 0 | D42: =IFERROR(C42/B42,0) -> 0
A44: G4 is separate fleet-scale qualification: feature completion does not certify 10 billion messages/day or grant provider approval.

Sheet Feature Tracker
A1: FEATURE DELIVERY & ASSIGNMENT
A2: Editable: Assignee, Status, Evidence, Estimate, Start, Due and Notes. Provider approval requires its own evidence.
A5: Task ID | B5: Domain | C5: Feature / work package | D5: Gate | E5: Priority | F5: Squad | G5: Assignee | H5: Predecessor IDs | I5: Status | J5: Verified completion | K5: Acceptance criteria | L5: Proposed code ownership | M5: Acceptance test ID | N5: Evidence link | O5: Estimate days | P5: Start date | Q5: Due date | R5: Sources | S5: Notes | T5: Evidence gate | U5: Overdue flag
A6: GOV-001 | B6: Architecture and governance | C6: Baseline, ADRs and change control | D6: G0 | E6: P0 | F6: Architecture | I6: Not started | J6: =IF(AND(I6="Done",N6<>""),1,0) -> 0 | K6: Scope IDs, ADR ownership and compatibility rules are approved; no silent requirement deletion. | L6: docs/architecture/; docs/decisions/ (proposed) | M6: AT-GOV-001 | R6: S01 | S6: Proposed target paths; no repository implementation inspected. Completion requires linked evidence. | T6: =IF(I6="Done",IF(N6="","MISSING EVIDENCE","Review evidence"),"Pending") -> Pending | U6: =IF(AND(Q6<>"",Q6<TODAY(),I6<>"Done"),"OVERDUE","")
A7: GOV-002 | B7: Architecture and governance | C7: Version and dependency bill of materials | D7: G0 | E7: P0 | F7: Architecture | I7: Not started | J7: =IF(AND(I7="Done",N7<>""),1,0) -> 0 | K7: All production dependencies and images are pinned with SBOM, licenses, support dates and reproducible build evidence. | L7: docs/architecture/; docs/decisions/ (proposed) | M7: AT-GOV-002 | R7: S01 | S7: Proposed target paths; no repository implementation inspected. Completion requires linked evidence. | T7: =IF(I7="Done",IF(N7="","MISSING EVIDENCE","Review evidence"),"Pending") -> Pending | U7: =IF(AND(Q7<>"",Q7<TODAY(),I7<>"Done"),"OVERDUE","")
A8: GOV-003 | B8: Architecture and governance | C8: Provider capability evidence register | D8: G0 | E8: P0 | F8: Architecture | I8: Not started | J8: =IF(AND(I8="Done",N8<>""),1,0) -> 0 | K8: Every externally exposed capability has version, permission, eligibility, source date and contract-test evidence. | L8: docs/architecture/; docs/decisions/ (proposed) | M8: AT-GOV-003 | R8: S01 | S8: Proposed target paths; no repository implementation inspected. Completion requires linked evidence. | T8: =IF(I8="Done",IF(N8="","MISSING EVIDENCE","Review evidence"),"Pending") -> Pending | U8: =IF(AND(Q8<>"",Q8<TODAY(),I8<>"Done"),"OVERDUE","")
A9: GOV-004 | B9: Architecture and governance | C9: Threat model and abuse cases | D9: G0 | E9: P0 | F9: Architecture | I9: Not started | J9: =IF(AND(I9="Done",N9<>""),1,0) -> 0 | K9: Cross-tenant, SSRF, token theft, duplicate payment, prompt injection and platform-abuse cases have mitigations and tests. | L9: docs/architecture/; docs/decisions/ (proposed) | M9: AT-GOV-004 | R9: S01 | S9: Proposed target paths; no repository implementation inspected. Completion requires linked evidence. | T9: =IF(I9="Done",IF(N9="","MISSING EVIDENCE","Review evidence"),"Pending") -> Pending | U9: =IF(AND(Q9<>"",Q9<TODAY(),I9<>"Done"),"OVERDUE","")
A10: GOV-005 | B10: Architecture and governance | C10: Data classification and residency matrix | D10: G0 | E10: P0 | F10: Architecture | I10: Not started | J10: =IF(AND(I10="Done",N10<>""),1,0) -> 0 | K10: Every data class has owner, processor purpose, location, retention and deletion path. | L10: docs/architecture/; docs/decisions/ (proposed) | M10: AT-GOV-005 | R10: S01 | S10: Proposed target paths; no repository implementation inspected. Completion requires linked evidence. | T10: =IF(I10="Done",IF(N10="","MISSING EVIDENCE","Review evidence"),"Pending") -> Pending | U10: =IF(AND(Q10<>"",Q10<TODAY(),I10<>"Done"),"OVERDUE","")
A11: GOV-006 | B11: Architecture and governance | C11: Release decision and exceptions process | D11: G0 | E11: P0 | F11: Architecture | I11: Not started | J11: =IF(AND(I11="Done",N11<>""),1,0) -> 0 | K11: No critical security or policy gate can be waived by an ordinary developer or sales administrator. | L11: docs/architecture/; docs/decisions/ (proposed) | M11: AT-GOV-006 | R11: S01 | S11: Proposed target paths; no repository implementation inspected. Completion requires linked evidence. | T11: =IF(I11="Done",IF(N11="","MISSING EVIDENCE","Review evidence"),"Pending") -> Pending | U11: =IF(AND(Q11<>"",Q11<TODAY(),I11<>"Done"),"OVERDUE","")
A12: GOV-007 | B12: Architecture and governance | C12: Capacity and cost approval | D12: G0 | E12: P0 | F12: Architecture | I12: Not started | J12: =IF(AND(I12="Done",N12<>""),1,0) -> 0 | K12: Workbook assumptions are replaced by measured workload distributions and vendor quotas before scale claims. | L12: docs/architecture/; docs/decisions/ (proposed) | M12: AT-GOV-007 | R12: S01 | S12: Proposed target paths; no repository implementation inspected. Completion requires linked evidence. | T12: =IF(I12="Done",IF(N12="","MISSING EVIDENCE","Review evidence"),"Pending") -> Pending | U12: =IF(AND(Q12<>"",Q12<TODAY(),I12<>"Done"),"OVERDUE","")
A13: PLT-001 | B13: Tenant platform | C13: Organization, workspace and environment model | D13: G0 | E13: P0 | F13: Platform | H13: GOV-001 | I13: Not started | J13: =IF(AND(I13="Done",N13<>""),1,0) -> 0 | K13: Server-created tenant/workspace/environment context propagates to every read, write and event. | L13: services/core/platform/; infra/terraform/ (proposed) | M13: AT-PLT-001 | R13: S15 | S13: Proposed target paths; no repository implementation inspected. Completion requires linked evidence. | T13: =IF(I13="Done",IF(N13="","MISSING EVIDENCE","Review evidence"),"Pending") -> Pending | U13: =IF(AND(Q13<>"",Q13<TODAY(),I13<>"Done"),"OVERDUE","")
A14: PLT-002 | B14: Tenant platform | C14: Identity, login and MFA | D14: G0 | E14: P0 | F14: Platform | H14: GOV-001 | I14: Not started | J14: =IF(AND(I14="Done",N14<>""),1,0) -> 0 | K14: Login, recovery, MFA, session revocation and account enumeration controls pass security tests. | L14: services/core/platform/; infra/terraform/ (proposed) | M14: AT-PLT-002 | R14: S15 | S14: Proposed target paths; no repository implementation inspected. Completion requires linked evidence. | T14: =IF(I14="Done",IF(N14="","MISSING EVIDENCE","Review evidence"),"Pending") -> Pending | U14: =IF(AND(Q14<>"",Q14<TODAY(),I14<>"Done"),"OVERDUE","")
A15: PLT-003 | B15: Tenant platform | C15: Role and attribute authorization | D15: G0 | E15: P0 | F15: Platform | H15: GOV-001 | I15: Not started | J15: =IF(AND(I15="Done",N15<>""),1,0) -> 0 | K15: Owner/admin/agent/developer/billing/custom roles are enforced on API, background and realtime paths. | L15: services/core/platform/; infra/terraform/ (proposed) | M15: AT-PLT-003 | R15: S15 | S15: Proposed target paths; no repository implementation inspected. Completion requires linked evidence. | T15: =IF(I15="Done",IF(N15="","MISSING EVIDENCE","Review evidence"),"Pending") -> Pending | U15: =IF(AND(Q15<>"",Q15<TODAY(),I15<>"Done"),"OVERDUE","")
A16: PLT-004 | B16: Tenant platform | C16: Cell directory and signed placement | D16: G0 | E16: P0 | F16: Platform | H16: GOV-001 | I16: Not started | J16: =IF(AND(I16="Done",N16<>""),1,0) -> 0 | K16: Tenant/account routes resolve with versioned cell assignment and ownership epoch; unknown routes fail closed. | L16: services/core/platform/; infra/terraform/ (proposed) | M16: AT-PLT-004 | R16: S15 | S16: Proposed target paths; no repository implementation inspected. Completion requires linked evidence. | T16: =IF(I16="Done",IF(N16="","MISSING EVIDENCE","Review evidence"),"Pending") -> Pending | U16: =IF(AND(Q16<>"",Q16<TODAY(),I16<>"Done"),"OVERDUE","")
A17: PLT-005 | B17: Tenant platform | C17: Tenant provisioning saga | D17: G0 | E17: P0 | F17: Platform | H17: GOV-001 | I17: Not started | J17: =IF(AND(I17="Done",N17<>""),1,0) -> 0 | K17: Retries create one tenant, one billing profile and one initial workspace; failed provisioning is recoverable. | L17: services/core/platform/; infra/terraform/ (proposed) | M17: AT-PLT-005 | R17: S15 | S17: Proposed target paths; no repository implementation inspected. Completion requires linked evidence. | T17: =IF(I17="Done",IF(N17="","MISSING EVIDENCE","Review evidence"),"Pending") -> Pending | U17: =IF(AND(Q17<>"",Q17<TODAY(),I17<>"Done"),"OVERDUE","")
A18: PLT-006 | B18: Tenant platform | C18: Configuration snapshot distribution | D18: G0 | E18: P0 | F18: Platform | H18: GOV-001 | I18: Not started | J18: =IF(AND(I18="Done",N18<>""),1,0) -> 0 | K18: Healthy cell processes existing workloads during global control-plane outage using valid signed snapshots. | L18: services/core/platform/; infra/terraform/ (proposed) | M18: AT-PLT-006 | R18: S15 | S18: Proposed target paths; no repository implementation inspected. Completion requires linked evidence. | T18: =IF(I18="Done",IF(N18="","MISSING EVIDENCE","Review evidence"),"Pending") -> Pending | U18: =IF(AND(Q18<>"",Q18<TODAY(),I18<>"Done"),"OVERDUE","")
A19: PLT-007 | B19: Tenant platform | C19: Feature entitlements and quotas | D19: G0 | E19: P0 | F19: Platform | H19: GOV-001 | I19: Not started | J19: =IF(AND(I19="Done",N19<>""),1,0) -> 0 | K19: Plans enforce feature, cost and volume limits without hardcoded plan-name branches. | L19: services/core/platform/; infra/terraform/ (proposed) | M19: AT-PLT-007 | R19: S15 | S19: Proposed target paths; no repository implementation inspected. Completion requires linked evidence. | T19: =IF(I19="Done",IF(N19="","MISSING EVIDENCE","Review evidence"),"Pending") -> Pending | U19: =IF(AND(Q19<>"",Q19<TODAY(),I19<>"Done"),"OVERDUE","")
A20: PLT-008 | B20: Tenant platform | C20: Secrets and credential references | D20: G0 | E20: P0 | F20: Platform | H20: GOV-001 | I20: Not started | J20: =IF(AND(I20="Done",N20<>""),1,0) -> 0 | K20: Secrets never appear in browser, logs, exports or workflow definitions; rotation is audited. | L20: services/core/platform/; infra/terraform/ (proposed) | M20: AT-PLT-008 | R20: S15 | S20: Proposed target paths; no repository implementation inspected. Completion requires linked evidence. | T20: =IF(I20="Done",IF(N20="","MISSING EVIDENCE","Review evidence"),"Pending") -> Pending | U20: =IF(AND(Q20<>"",Q20<TODAY(),I20<>"Done"),"OVERDUE","")
A21: PLT-009 | B21: Tenant platform | C21: Agency delegation isolation | D21: G0 | E21: P0 | F21: Platform | H21: GOV-001 | I21: Not started | J21: =IF(AND(I21="Done",N21<>""),1,0) -> 0 | K21: Partner permissions require explicit tenant grants and do not create implicit cross-tenant data visibility. | L21: services/core/platform/; infra/terraform/ (proposed) | M21: AT-PLT-009 | R21: S15 | S21: Proposed target paths; no repository implementation inspected. Completion requires linked evidence. | T21: =IF(I21="Done",IF(N21="","MISSING EVIDENCE","Review evidence"),"Pending") -> Pending | U21: =IF(AND(Q21<>"",Q21<TODAY(),I21<>"Done"),"OVERDUE","")
A22: PLT-010 | B22: Tenant platform | C22: Offboarding and tenant suspension | D22: G0 | E22: P0 | F22: Platform | H22: GOV-001 | I22: Not started | J22: =IF(AND(I22="Done",N22<>""),1,0) -> 0 | K22: Suspension blocks new sends and sensitive reads; durable incoming data follows documented retention policy. | L22: services/core/platform/; infra/terraform/ (proposed) | M22: AT-PLT-010 | R22: S15 | S22: Proposed target paths; no repository implementation inspected. Completion requires linked evidence. | T22: =IF(I22="Done",IF(N22="","MISSING EVIDENCE","Review evidence"),"Pending") -> Pending | U22: =IF(AND(Q22<>"",Q22<TODAY(),I22<>"Done"),"OVERDUE","")
A23: PLT-011 | B23: Tenant platform | C23: Tenant migration fencing | D23: G2 | E23: P1 | F23: Platform | H23: GOV-001 | I23: Not started | J23: =IF(AND(I23="Done",N23<>""),1,0) -> 0 | K23: Old and new cells cannot both execute side effects during cutover; event reconciliation passes. | L23: services/core/platform/; infra/terraform/ (proposed) | M23: AT-PLT-011 | R23: S15 | S23: Proposed target paths; no repository implementation inspected. Completion requires linked evidence. | T23: =IF(I23="Done",IF(N23="","MISSING EVIDENCE","Review evidence"),"Pending") -> Pending | U23: =IF(AND(Q23<>"",Q23<TODAY(),I23<>"Done"),"OVERDUE","")
A24: PLT-012 | B24: Tenant platform | C24: Developer sandbox isolation | D24: G0 | E24: P0 | F24: Platform | H24: GOV-001 | I24: Not started | J24: =IF(AND(I24="Done",N24<>""),1,0) -> 0 | K24: Sandbox cannot obtain production credentials or address real customers through any action path. | L24: services/core/platform/; infra/terraform/ (proposed) | M24: AT-PLT-012 | R24: S15 | S24: Proposed target paths; no repository implementation inspected. Completion requires linked evidence. | T24: =IF(I24="Done",IF(N24="","MISSING EVIDENCE","Review evidence"),"Pending") -> Pending | U24: =IF(AND(Q24<>"",Q24<TODAY(),I24<>"Done"),"OVERDUE","")
... A267: ECO-008 | B267: Agency and marketplace | C267: Industry packs and partner enablement | D267: G3 | E267: P1 | F267: Ecosystem | H267: PLT-009, BIL-003 | I267: Not started | J267: =IF(AND(I267="Done",N267<>""),1,0) -> 0 | K267: Four initial vertical packs include sample data, tests, docs, support and measurable launch outcomes. | L267: services/core/ecosystem/ (proposed) | M267: AT-ECO-008 | R267: S01 | S267: Proposed target paths; no repository implementation inspected. Completion requires linked evidence. | T267: =IF(I267="Done",IF(N267="","MISSING EVIDENCE","Review evidence"),"Pending") -> Pending | U267: =IF(AND(Q267<>"",Q267<TODAY(),I267<>"Done"),"OVERDUE","")

Sheet Capacity Model
A1: CAPACITY & STORAGE MODEL
A2: Blue values are editable planning assumptions. Outputs are calculations, not measured capacity or provider authorization.
A5: Input parameter | B5: Value | C5: Units | D5: Source / meaning
A6: Registered tenants | B6: 10000000 | C6: tenants | D6: User target; not concurrent active sessions
A7: Logical messages per day | B7: 10000000000 | C7: messages/day | D7: User target; excludes receipts and retries
A8: Seconds per day | B8: 86400 | C8: seconds | D8: Arithmetic constant
A9: Peak-to-average factor | B9: 10 | C9: factor | D9: Planning assumption; replace using measured demand
A10: Events per logical message | B10: 4 | C10: events/message | D10: Combined event model, not provider guarantee
A11: Retry / duplicate allowance | B11: 0.1 | C11: fraction | D11: Extra transported events
A12: Canonical event size | B12: 1024 | C12: bytes | D12: Mean excluding media; p95/p99 sizes also required
A13: Topic copy factor | B13: 2 | C13: copies | D13: Raw / canonical / derived aggregate copy allowance
A14: Compressed/original ratio | B14: 0.5 | C14: fraction | D14: Must be benchmarked on real payload shapes
A15: Kafka replication factor | B15: 3 | C15: replicas | D15: In-region replicas; not regional DR
A16: Kafka retention | B16: 2 | C16: days | D16: Separate from archive retention
A17: Maximum planned utilization | B17: 0.6 | C17: fraction | D17: Reserved headroom; does not prove performance
... A33: Bytes per decimal PB | B33: 1e+15 | C33: bytes/PB | D33: Decimal display conversion
A36: Calculated output | B36: Value | C36: Units | D36: Formula interpretation
A37: Average logical messages/second | B37: =B7/B8 -> 115740.74 | C37: messages/s | D37: Daily logical messages / seconds
A38: Peak logical messages/second | B38: =B37*B9 -> 1157407.4 | C38: messages/s | D38: Average × assumed peak factor
A39: Transported canonical events/day | B39: =B7*B10*(1+B11) -> 44000000000 | C39: events/day | D39: Message count × event amplification × retries
A40: Average events/second | B40: =B39/B8 -> 509259.26 | C40: events/s | D40: Transported canonical events/day / seconds
A41: Peak events/second | B41: =B40*B9 -> 5092592.6 | C41: events/s | D41: Average event rate × peak
A42: Canonical original data/day | B42: =B39*B12/B32 -> 45.056 | C42: TB/day | D42: Before compression, topic copies or replicas
A43: Kafka storage at planned utilization | B43: =B42*B13*B14*B15*B16/B17 -> 450.56 | C43: TB | D43: Copies × compression × replicas × days / utilization
A44: Primary message bytes/day | B44: =B7*B18/B32 -> 40.96 | C44: TB/day | D44: Message records only; excludes indexes/replicas
A45: Hot message record storage | B45: =B44*B19 -> 286.72 | C45: TB | D45: Primary records × hot retention
A46: Archive message storage | B46: =B7*B18*B20/B33 -> 1.2288 | C46: PB | D46: Uncompressed message records × archive days
A47: Media bytes/day | B47: =B7*B21*B22/B32 -> 262.144 | C47: TB/day | D47: Media fraction × mean size
A48: Hot media storage | B48: =B47*B23*B32/B33 -> 1.835008 | C48: PB | D48: Media bytes × retention
A49: AI calls/day | B49: =B7*B24*B25 -> 500000000 | C49: calls/day | D49: Selected messages × calls per selection
A50: Average AI calls/second | B50: =B49/B8 -> 5787.037 | C50: calls/s | D50: Daily calls / seconds
A51: Peak AI calls/second | B51: =B50*B9 -> 57870.37 | C51: calls/s | D51: Average calls × peak
A52: AI input tokens/day | B52: =B49*B26 -> 400000000000 | C52: tokens/day | D52: Daily calls × input tokens
A53: AI output tokens/day | B53: =B49*B27 -> 100000000000 | C53: tokens/day | D53: Daily calls × output tokens
A54: Workflow starts/day | B54: =B7*B28 -> 200000000 | C54: starts/day | D54: Logical messages × selected-start fraction
A55: Average workflow starts/second | B55: =B54/B8 -> 2314.8148 | C55: starts/s | D55: Daily starts / seconds
A56: Peak workflow starts/second | B56: =B55*B9 -> 23148.148 | C56: starts/s | D56: Average starts × peak
A57: Tenant-count cell lower bound | B57: =ROUNDUP(B6/B29,0) -> 200 | C57: cells | D57: Only tenancy constraint, no skew
A58: Event-rate cell lower bound | B58: =ROUNDUP(B41/(B30*B17),0) -> 170 | C58: cells | D58: Only event constraint with utilization headroom
A59: Combined arithmetic lower bound | B59: =MAX(B57,B58) -> 200 | C59: cells | D59: Other dimensions can require more cells
...

Sheet Release Gates
A1: RELEASE & SCALE GATES
A2: A release gate is an evidence decision, not a percentage inferred from UI completion.
A5: Gate | B5: Name | C5: Accountable roles | D5: Scope | E5: Exit evidence | F5: Status | G5: Evidence link
A6: G0 | B6: Foundation | C6: Architecture / Platform / Security | D6: Isolation, contracts, journals, policy, CI and sandbox baseline | E6: Critical negative/security/ACK tests; named source-verification owner | F6: Not started
A7: G1 | B7: Controlled pilot | C7: Channels / Messaging / Automation / QA | D7: One real end-to-end permitted Mission with inbox, workflows, AI, webhooks and support | E7: Onboarding and approval evidence, crash-window tests, rollback and support readiness | F7: Not started
A8: G2 | B8: General product | C8: Business / Integrations / SRE | D8: Broader channels, commerce, integrations, billing and regional recovery | E8: Product acceptance, policy validation, reconciliation, restore and unit economics | F8: Not started
A9: G3 | B9: Advanced ecosystem | C9: Voice / Ecosystem / Security | D9: Conditional voice, marketplace, reseller, enterprise deployment | E9: Provider eligibility, package review, enterprise isolation and commercial demand | F9: Not started
A10: G4 | B10: Hyperscale certification | C10: SRE / Performance QA / Provider operations | D10: Admitted cell fleet supporting qualified 10m tenants / 10b messages-day envelope | E10: Actual peak/skew/storage/AI/provider capacity and regional recovery evidence | F10: Not started

Sheet Approval Gates
A1: APPROVAL & OPEN-DECISION REGISTER
A2: All items below need named ownership and linked evidence. Exact current Meta access/quotas were not fully retrievable.
A5: Decision ID | B5: Decision | C5: Accountable roles | D5: Required evidence | E5: Gate | F5: Status | G5: Evidence link
A6: OD-01 | B6: Actual workload shape | C6: Architecture + Product | D6: Inbound/outbound/receipt mix, peak distribution and top-tenant skew | E6: Before capacity certification | F6: Not started
A7: OD-02 | B7: Current Meta signup, scopes and quotas | C7: Channels + Provider operations | D7: Official current signup, App Review, permissions and account/onboarding quota evidence | E7: Before Meta submission | F7: Not started
A8: OD-03 | B8: App topology and data residency | C8: Channels + Legal + Security | D8: Decide single App ID and callback routing; approve locality for mixed-asset bodies | E8: Before strict-residency commitments | F8: Not started
A9: OD-04 | B9: AI/data-use restrictions | C9: Legal + AI | D9: Approve channel-specific business purpose, processing, training and model restrictions | E9: Before AI production access | F9: Not started
A10: OD-05 | B10: Contractual DR service tiers | C10: SRE + Legal + Sales | D10: Measured RPO/RTO and residency contract; asynchronous DR is not zero loss | E10: Before SLA publication | F10: Not started
A11: OD-06 | B11: Media, AI, voice and retention | C11: Product + Finance + SRE | D11: Measured fractions, sizes, tokens, concurrent calls and webhook fanout | E11: Before production cost commitment | F11: Not started
A12: OD-07 | B12: Cell hardware/software qualification | C12: SRE + Performance QA | D12: Pinned bill of materials, production-like cell benchmark and soak evidence | E12: Before each capacity claim | F12: Not started
A13: OD-08 | B13: Staffing and operational budget | C13: Leadership | D13: Named owners, on-call/support coverage, infrastructure and provider funding | E13: Before commercial release | F13: Not started
A14: OD-09 | B14: Actual repository audit | C14: Engineering | D14: Inspect current code, dependencies, security posture and migration plan | E14: Before applying proposed layout | F14: Not started
A15: OD-10 | B15: Market-specific legal obligations | C15: Legal + Security | D15: Privacy, tax, payments, recording and regulated-data applicability | E15: Before corresponding market/feature | F15: Not started
A16: OD-11 | B16: Production volume and conditional channels | C16: Provider operations | D16: Provider account/number/app volume permission and optional feature eligibility | E16: Before scale or conditional-feature activation | F16: Not started
A17: OD-12 | B17: Licenses, cloud quotas and contracts | C17: Engineering + Procurement | D17: SDK/model licenses, cloud limits and service agreements | E17: Before provider selection is contracted | F17: Not started

Sheet Traceability
A1: APPROVED SCOPE TRACEABILITY
A2: All 61 numbered source sections are mapped. Conceptual market and forecast claims are not converted into verified facts.
A5: Source section | B5: Approved source heading | C5: Type | D5: Work-package groups | E5: Architecture sections | F5: Interpretation / constraint
A6: 1 | B6: What the market already has | C6: Product context / governed claim | D6: GOV | E6: 1, 35 | F6: Not evidence of uniqueness, market penetration or completed capability.
A7: 2 | B7: The category I would build | C7: Retained requirement | D7: GOV,PLT | E7: 2 | F7: Implementation split across listed work-package groups; external capabilities remain eligibility gated.
A8: 3 | B8: The real innovation: Mission, not Workflow | C8: Retained requirement | D8: MIS | E8: 6, 17 | F8: Implementation split across listed work-package groups; external capabilities remain eligibility gated.
A9: 4 | B9: Mission Compiler | C9: Retained requirement | D9: MIS,AIG | E9: 17, 21 | F9: Implementation split across listed work-package groups; external capabilities remain eligibility gated.
A10: 5 | B10: Unique layer #2: Full-Stack Journey Twin | C10: Retained requirement | D10: SIM | E10: 20 | F10: Implementation split across listed work-package groups; external capabilities remain eligibility gated.
A11: 6 | B11: Simulation output | C11: Retained requirement | D11: SIM | E11: 20 | F11: Retained simulator/shadow feature; earlier numeric conversion examples are illustrative, not evidence or valid counterfactual uplift.
A12: 7 | B12: Unique layer #3: Provider Twin | C12: Retained requirement | D12: WHA,INS,TGM | E12: 11, 17 | F12: Implementation split across listed work-package groups; external capabilities remain eligibility gated.
A13: 8 | B13: Unique layer #4: Channel-Native Experience Compiler | C13: Retained requirement | D13: MIS | E13: 17 | F13: Implementation split across listed work-package groups; external capabilities remain eligibility gated.
A14: 9 | B14: Unique layer #5: Provider Change Radar | C14: Retained requirement | D14: SIM,GOV | E14: 20, 34 | F14: Implementation split across listed work-package groups; external capabilities remain eligibility gated.
A15: 10 | B15: Unique layer #6: Action Receipt | C15: Retained requirement | D15: ACT | E15: 19 | F15: Implementation split across listed work-package groups; external capabilities remain eligibility gated.
A16: 11 | B16: Unique layer #7: Adaptive Autonomy | C16: Retained requirement | D16: ACT,AIG | E16: 19, 21 | F16: Implementation split across listed work-package groups; external capabilities remain eligibility gated.
A17: 12 | B17: Shadow Runtime | C17: Retained requirement | D17: SIM | E17: 20 | F17: Retained simulator/shadow feature; earlier numeric conversion examples are illustrative, not evidence or valid counterfactual uplift.
... A66: 61 | B66: Final definition | C66: Product context / governed claim | D66: GOV,MIS | E66: 1, 2, 35 | F66: Not evidence of uniqueness, market penetration or completed capability.

Sheet Sources
A1: RESEARCH & SOURCE REGISTER
A2: As of 7 September 2026. Retrieval failures and partial text are explicit; reverify provider contracts before release.
A5: Source ID | B5: Source / title | C5: URL / uploaded filename | D5: Used for | E5: Retrieval status
A6: S01 | B6: Approved user scope | C6: Pasted markdown(20260906-222954).md | D6: User-provided baseline; product scope, not independent verification | E6: Uploaded source
A7: S02 | B7: WhatsApp partner ecosystem | C7: https://whatsappbusiness.com/partners/become-a-partner/ | D7: Tech Provider path; Solution Partner credit-line distinction | E7: Read
A8: S03 | B8: WhatsApp Business Messaging Policy | C8: https://whatsappbusiness.com/policy/ | D8: Consent, service window, templates, escalation, restricted uses | E8: Read
A9: S04 | B9: WhatsApp Business Solution Terms | C9: https://www.whatsapp.com/legal/business-solution-terms | D9: March 6, 2026 text; AI/data-processing restrictions require legal release review | E9: Read
A10: S05 | B10: WhatsApp platform pricing | C10: https://whatsappbusiness.com/products/platform-pricing/ | D10: Delivered-message charging and category/market pricing; do not freeze rate cards | E10: Read
A11: S06 | B11: WhatsApp Developer Hub | C11: https://whatsappbusiness.com/developers/developer-hub/ | D11: Official entry points for API, webhooks, limits, enforcement and changes | E11: Read
A12: S07 | B12: WhatsApp Calling announcement | C12: https://whatsappbusiness.com/blog/whatsapp-business-calling-api/ | D12: Calling and business-initiated permission; endpoint details separately gated | E12: Read
A13: S08 | B13: Tech Provider onboarding | C13: https://developers.facebook.com/documentation/business-messaging/whatsapp/solution-providers/get-started-for-tech-providers/ | D13: Exact dashboard checklist must be captured during implementation | E13: Not retrieved: cache/HTTP restriction
A14: S09 | B14: WhatsApp Cloud API overview | C14: https://developers.facebook.com/docs/whatsapp/cloud-api/overview | D14: Throughput, app/asset quotas and retry horizon must be revalidated | E14: Not retrieved: HTTP 429
A15: S10 | B15: Embedded Signup overview | C15: https://developers.facebook.com/documentation/business-messaging/whatsapp/embedded-signup/overview | D15: Configuration version and customer-token exchange contract require live validation | E15: Not retrieved: HTTP restriction
A16: S11 | B16: Meta Graph Webhooks setup | C16: https://developers.facebook.com/docs/graph-api/webhooks/getting-started | D16: Challenge/signature adapter must be verified against live Meta fixtures | E16: Not retrieved: HTTP restriction
... A40: S35 | B40: GDPR official legislation | C40: https://eur-lex.europa.eu/eli/reg/2016/679/oj/eng | D40: Counsel review of applicable controller/processor obligations | E40: Landing page only; substantive text unavailable

Sheet INC-014 Evidence
A1: # INC-014: Windows frontend preview launcher
A3: Date: 8 September 2026. Bounded local frontend utility, related to UX-003;
A4: no original work-package status is certified complete.
A6: The owner requested a one-click `start.bat`. The checkout lacked the frontend
A7: manifest and entry points. The supplied structured-v1 ZIP was found in Downloads;
A8: its SHA-256 is `9fe4185159b137cd94346265dd3e385b5aa9e3803bffbee9b31591a4f6291c23`,
A9: exactly matching the persistent source register. The baseline tracker was also
A10: found locally with its registered SHA-256. No re-upload was needed.
A12: ## Changed paths and value
A14: - `start.bat`: location-independent Windows entry point, Node/npm prerequisite
A15: checks, locked `npm ci` on first launch, existing `dev:frontend` command and
A16: browser opening at `http://127.0.0.1:5174/frontend-preview`. Port conflicts fail
... A72: Original eight baseline sheets and all original work-package statuses preserved.
